Traceback (most recent call last):
  File "/home/john/anaconda3/lib/python3.8/site-packages/jupyter_cache/executors/utils.py", line 51, in single_nb_execution
    executenb(
  File "/home/john/anaconda3/lib/python3.8/site-packages/nbclient/client.py", line 1087, in execute
    return NotebookClient(nb=nb, resources=resources, km=km, **kwargs).execute()
  File "/home/john/anaconda3/lib/python3.8/site-packages/nbclient/util.py", line 74, in wrapped
    return just_run(coro(*args, **kwargs))
  File "/home/john/anaconda3/lib/python3.8/site-packages/nbclient/util.py", line 53, in just_run
    return loop.run_until_complete(coro)
  File "/home/john/anaconda3/lib/python3.8/asyncio/base_events.py", line 616, in run_until_complete
    return future.result()
  File "/home/john/anaconda3/lib/python3.8/site-packages/nbclient/client.py", line 540, in async_execute
    await self.async_execute_cell(
  File "/home/john/anaconda3/lib/python3.8/site-packages/nbclient/client.py", line 832, in async_execute_cell
    self._check_raise_for_error(cell, exec_reply)
  File "/home/john/anaconda3/lib/python3.8/site-packages/nbclient/client.py", line 740, in _check_raise_for_error
    raise CellExecutionError.from_cell_and_msg(cell, exec_reply['content'])
nbclient.exceptions.CellExecutionError: An error occurred while executing the following cell:
------------------
import numpy as np
from matplotlib.pyplot import plt

xmin, xmax = -10.0, 10.0
ymin, ymax = -5.0,  5.0

ax.set_xlim(xmin, xmax)
ax.set_ylim(ymin, ymax)

A1 = np.asarray([[0.58, -0.6],
                 [0.65, 0.3]])

def f(x, y): A1 @ (x, y)

def draw_arrow(x, y, ax):
    eps = 0.0001
    v1, v2 = f(x, y)
    nrm = np.sqrt(v1**2 + v2**2)
    scale = eps / nrm
    ax.arrow(x, y, scale * v1, scale * v2,
            antialiased=True, 
            alpha=0.8,
            head_length=0.025*(xmax - xmin), 
            head_width=0.012*(xmax - xmin),
            fill=False)

xgrid = np.linspace(xmin * 1.1, xmax * 0.95, 12)
ygrid = np.linspace(ymin * 1.1, ymax * 0.95, 12)

fig, ax = plt.subplots()

for x in xgrid:
    for y in ygrid:
        draw_arrow(x, y, ax)

plt.show()

------------------

[0;31m---------------------------------------------------------------------------[0m
[0;31mImportError[0m                               Traceback (most recent call last)
[0;32m<ipython-input-2-be715307aa75>[0m in [0;36m<module>[0;34m[0m
[1;32m      1[0m [0;32mimport[0m [0mnumpy[0m [0;32mas[0m [0mnp[0m[0;34m[0m[0;34m[0m[0m
[0;32m----> 2[0;31m [0;32mfrom[0m [0mmatplotlib[0m[0;34m.[0m[0mpyplot[0m [0;32mimport[0m [0mplt[0m[0;34m[0m[0;34m[0m[0m
[0m[1;32m      3[0m [0;34m[0m[0m
[1;32m      4[0m [0mxmin[0m[0;34m,[0m [0mxmax[0m [0;34m=[0m [0;34m-[0m[0;36m10.0[0m[0;34m,[0m [0;36m10.0[0m[0;34m[0m[0;34m[0m[0m
[1;32m      5[0m [0mymin[0m[0;34m,[0m [0mymax[0m [0;34m=[0m [0;34m-[0m[0;36m5.0[0m[0;34m,[0m  [0;36m5.0[0m[0;34m[0m[0;34m[0m[0m

[0;31mImportError[0m: cannot import name 'plt' from 'matplotlib.pyplot' (/home/john/anaconda3/lib/python3.8/site-packages/matplotlib/pyplot.py)
ImportError: cannot import name 'plt' from 'matplotlib.pyplot' (/home/john/anaconda3/lib/python3.8/site-packages/matplotlib/pyplot.py)

